2022-05-02 08:03:36|   ERROR|testAction.py[:148]|日期不在允许范围内
Traceback (most recent call last):
  File "/Users/ziqguo/Documents/testdev/testProject/testProject/testAction.py", line 131, in orderAddCommit
    raise Exception("日期不在允许范围内")
Exception: 日期不在允许范围内
2022-05-02 08:03:36|   ERROR|testAction.py[:148]|日期不在允许范围内
Traceback (most recent call last):
  File "/Users/ziqguo/Documents/testdev/testProject/testProject/testAction.py", line 131, in orderAddCommit
    raise Exception("日期不在允许范围内")
Exception: 日期不在允许范围内
2022-05-02 08:03:36|   ERROR|testAction.py[:148]|日期不在允许范围内
Traceback (most recent call last):
  File "/Users/ziqguo/Documents/testdev/testProject/testProject/testAction.py", line 131, in orderAddCommit
    raise Exception("日期不在允许范围内")
Exception: 日期不在允许范围内
2022-05-02 08:03:36|   ERROR|testAction.py[:148]|日期不在允许范围内
Traceback (most recent call last):
  File "/Users/ziqguo/Documents/testdev/testProject/testProject/testAction.py", line 131, in orderAddCommit
    raise Exception("日期不在允许范围内")
Exception: 日期不在允许范围内
2022-05-02 08:03:36|   ERROR|testAction.py[:148]|日期不在允许范围内
Traceback (most recent call last):
  File "/Users/ziqguo/Documents/testdev/testProject/testProject/testAction.py", line 131, in orderAddCommit
    raise Exception("日期不在允许范围内")
Exception: 日期不在允许范围内
2022-05-02 08:03:36|   ERROR|testAction.py[:148]|日期不在允许范围内
Traceback (most recent call last):
  File "/Users/ziqguo/Documents/testdev/testProject/testProject/testAction.py", line 131, in orderAddCommit
    raise Exception("日期不在允许范围内")
Exception: 日期不在允许范围内
2022-05-02 08:03:36|   ERROR|testAction.py[:148]|日期不在允许范围内
Traceback (most recent call last):
  File "/Users/ziqguo/Documents/testdev/testProject/testProject/testAction.py", line 131, in orderAddCommit
    raise Exception("日期不在允许范围内")
Exception: 日期不在允许范围内
2022-05-02 08:03:36|   ERROR|testAction.py[:148]|日期不在允许范围内
Traceback (most recent call last):
  File "/Users/ziqguo/Documents/testdev/testProject/testProject/testAction.py", line 131, in orderAddCommit
    raise Exception("日期不在允许范围内")
Exception: 日期不在允许范围内
2022-05-02 08:03:36|   ERROR|testAction.py[:148]|日期不在允许范围内
Traceback (most recent call last):
  File "/Users/ziqguo/Documents/testdev/testProject/testProject/testAction.py", line 131, in orderAddCommit
    raise Exception("日期不在允许范围内")
Exception: 日期不在允许范围内
2022-05-02 08:03:36|   ERROR|testAction.py[:148]|日期不在允许范围内
Traceback (most recent call last):
  File "/Users/ziqguo/Documents/testdev/testProject/testProject/testAction.py", line 131, in orderAddCommit
    raise Exception("日期不在允许范围内")
Exception: 日期不在允许范围内
2022-05-02 08:07:35|   DEBUG|selector_events.py[:59]|Using selector: KqueueSelector
2022-05-02 08:07:35|   DEBUG|selector_events.py[:59]|Using selector: KqueueSelector
2022-05-04 06:24:43|   DEBUG|testAction.py[:57]|admin
2022-05-04 06:24:43|   DEBUG|testAction.py[:58]|123456
2022-05-04 06:24:44|    INFO|testAction.py[:78]|response json: {'code': 0}
2022-05-04 06:24:44|   ERROR|testAction.py[:148]|'order_dep'
Traceback (most recent call last):
  File "/Users/ziqguo/opt/anaconda3/envs/testProject/lib/python3.9/site-packages/django/utils/datastructures.py", line 76, in __getitem__
    list_ = super().__getitem__(key)
KeyError: 'order_dep'

During handling of the above exception, another exception occurred:

Traceback (most recent call last):
  File "/Users/ziqguo/Documents/testdev/testProject/testProject/testAction.py", line 122, in orderAddCommit
    order_dep = request.POST['order_dep']
  File "/Users/ziqguo/opt/anaconda3/envs/testProject/lib/python3.9/site-packages/django/utils/datastructures.py", line 78, in __getitem__
    raise MultiValueDictKeyError(key)
django.utils.datastructures.MultiValueDictKeyError: 'order_dep'
2022-05-04 06:24:44|   ERROR|testAction.py[:148]|日期不在允许范围内
Traceback (most recent call last):
  File "/Users/ziqguo/Documents/testdev/testProject/testProject/testAction.py", line 131, in orderAddCommit
    raise Exception("日期不在允许范围内")
Exception: 日期不在允许范围内
2022-05-04 06:24:44|   ERROR|testAction.py[:148]|日期不在允许范围内
Traceback (most recent call last):
  File "/Users/ziqguo/Documents/testdev/testProject/testProject/testAction.py", line 131, in orderAddCommit
    raise Exception("日期不在允许范围内")
Exception: 日期不在允许范围内
2022-05-04 06:24:44|   ERROR|testAction.py[:148]|日期不在允许范围内
Traceback (most recent call last):
  File "/Users/ziqguo/Documents/testdev/testProject/testProject/testAction.py", line 131, in orderAddCommit
    raise Exception("日期不在允许范围内")
Exception: 日期不在允许范围内
2022-05-04 06:24:44|   ERROR|testAction.py[:148]|日期不在允许范围内
Traceback (most recent call last):
  File "/Users/ziqguo/Documents/testdev/testProject/testProject/testAction.py", line 131, in orderAddCommit
    raise Exception("日期不在允许范围内")
Exception: 日期不在允许范围内
2022-05-04 06:24:44|   ERROR|testAction.py[:148]|'order_date'
Traceback (most recent call last):
  File "/Users/ziqguo/opt/anaconda3/envs/testProject/lib/python3.9/site-packages/django/utils/datastructures.py", line 76, in __getitem__
    list_ = super().__getitem__(key)
KeyError: 'order_date'

During handling of the above exception, another exception occurred:

Traceback (most recent call last):
  File "/Users/ziqguo/Documents/testdev/testProject/testProject/testAction.py", line 124, in orderAddCommit
    order_date = request.POST['order_date']
  File "/Users/ziqguo/opt/anaconda3/envs/testProject/lib/python3.9/site-packages/django/utils/datastructures.py", line 78, in __getitem__
    raise MultiValueDictKeyError(key)
django.utils.datastructures.MultiValueDictKeyError: 'order_date'
2022-05-04 06:24:44|   ERROR|testAction.py[:148]|日期不在允许范围内
Traceback (most recent call last):
  File "/Users/ziqguo/Documents/testdev/testProject/testProject/testAction.py", line 131, in orderAddCommit
    raise Exception("日期不在允许范围内")
Exception: 日期不在允许范围内
2022-05-04 06:24:44|   ERROR|testAction.py[:148]|日期不在允许范围内
Traceback (most recent call last):
  File "/Users/ziqguo/Documents/testdev/testProject/testProject/testAction.py", line 131, in orderAddCommit
    raise Exception("日期不在允许范围内")
Exception: 日期不在允许范围内
2022-05-04 06:24:44|   ERROR|testAction.py[:148]|日期不在允许范围内
Traceback (most recent call last):
  File "/Users/ziqguo/Documents/testdev/testProject/testProject/testAction.py", line 131, in orderAddCommit
    raise Exception("日期不在允许范围内")
Exception: 日期不在允许范围内
2022-05-04 06:24:44|   ERROR|testAction.py[:148]|日期不在允许范围内
Traceback (most recent call last):
  File "/Users/ziqguo/Documents/testdev/testProject/testProject/testAction.py", line 131, in orderAddCommit
    raise Exception("日期不在允许范围内")
Exception: 日期不在允许范围内
2022-05-04 06:24:44|   ERROR|testAction.py[:148]|日期不在允许范围内
Traceback (most recent call last):
  File "/Users/ziqguo/Documents/testdev/testProject/testProject/testAction.py", line 131, in orderAddCommit
    raise Exception("日期不在允许范围内")
Exception: 日期不在允许范围内
2022-05-04 06:24:44|   ERROR|testAction.py[:148]|日期不在允许范围内
Traceback (most recent call last):
  File "/Users/ziqguo/Documents/testdev/testProject/testProject/testAction.py", line 131, in orderAddCommit
    raise Exception("日期不在允许范围内")
Exception: 日期不在允许范围内
2022-05-04 06:24:44|   ERROR|testAction.py[:148]|日期不在允许范围内
Traceback (most recent call last):
  File "/Users/ziqguo/Documents/testdev/testProject/testProject/testAction.py", line 131, in orderAddCommit
    raise Exception("日期不在允许范围内")
Exception: 日期不在允许范围内
2022-05-04 06:24:44|   ERROR|testAction.py[:148]|日期不在允许范围内
Traceback (most recent call last):
  File "/Users/ziqguo/Documents/testdev/testProject/testProject/testAction.py", line 131, in orderAddCommit
    raise Exception("日期不在允许范围内")
Exception: 日期不在允许范围内
2022-05-04 06:24:44|   ERROR|testAction.py[:148]|日期不在允许范围内
Traceback (most recent call last):
  File "/Users/ziqguo/Documents/testdev/testProject/testProject/testAction.py", line 131, in orderAddCommit
    raise Exception("日期不在允许范围内")
Exception: 日期不在允许范围内
2022-05-04 06:24:44|   ERROR|testAction.py[:148]|日期不在允许范围内
Traceback (most recent call last):
  File "/Users/ziqguo/Documents/testdev/testProject/testProject/testAction.py", line 131, in orderAddCommit
    raise Exception("日期不在允许范围内")
Exception: 日期不在允许范围内
2022-05-04 06:24:44|   ERROR|testAction.py[:148]|日期不在允许范围内
Traceback (most recent call last):
  File "/Users/ziqguo/Documents/testdev/testProject/testProject/testAction.py", line 131, in orderAddCommit
    raise Exception("日期不在允许范围内")
Exception: 日期不在允许范围内
2022-05-04 06:24:44|   ERROR|testAction.py[:148]|日期不在允许范围内
Traceback (most recent call last):
  File "/Users/ziqguo/Documents/testdev/testProject/testProject/testAction.py", line 131, in orderAddCommit
    raise Exception("日期不在允许范围内")
Exception: 日期不在允许范围内
2022-05-04 06:24:44|   ERROR|testAction.py[:148]|日期不在允许范围内
Traceback (most recent call last):
  File "/Users/ziqguo/Documents/testdev/testProject/testProject/testAction.py", line 131, in orderAddCommit
    raise Exception("日期不在允许范围内")
Exception: 日期不在允许范围内
2022-05-04 06:24:44|   ERROR|testAction.py[:148]|日期不在允许范围内
Traceback (most recent call last):
  File "/Users/ziqguo/Documents/testdev/testProject/testProject/testAction.py", line 131, in orderAddCommit
    raise Exception("日期不在允许范围内")
Exception: 日期不在允许范围内
2022-05-04 06:24:44|   ERROR|testAction.py[:148]|日期不在允许范围内
Traceback (most recent call last):
  File "/Users/ziqguo/Documents/testdev/testProject/testProject/testAction.py", line 131, in orderAddCommit
    raise Exception("日期不在允许范围内")
Exception: 日期不在允许范围内
2022-05-04 06:24:44|   ERROR|testAction.py[:148]|日期不在允许范围内
Traceback (most recent call last):
  File "/Users/ziqguo/Documents/testdev/testProject/testProject/testAction.py", line 131, in orderAddCommit
    raise Exception("日期不在允许范围内")
Exception: 日期不在允许范围内
2022-05-04 06:24:44|   ERROR|testAction.py[:148]|日期不在允许范围内
Traceback (most recent call last):
  File "/Users/ziqguo/Documents/testdev/testProject/testProject/testAction.py", line 131, in orderAddCommit
    raise Exception("日期不在允许范围内")
Exception: 日期不在允许范围内
2022-05-04 06:24:44|   ERROR|testAction.py[:148]|日期不在允许范围内
Traceback (most recent call last):
  File "/Users/ziqguo/Documents/testdev/testProject/testProject/testAction.py", line 131, in orderAddCommit
    raise Exception("日期不在允许范围内")
Exception: 日期不在允许范围内
2022-05-04 06:24:44|   ERROR|testAction.py[:148]|日期不在允许范围内
Traceback (most recent call last):
  File "/Users/ziqguo/Documents/testdev/testProject/testProject/testAction.py", line 131, in orderAddCommit
    raise Exception("日期不在允许范围内")
Exception: 日期不在允许范围内
2022-05-04 06:24:44|   ERROR|testAction.py[:148]|日期不在允许范围内
Traceback (most recent call last):
  File "/Users/ziqguo/Documents/testdev/testProject/testProject/testAction.py", line 131, in orderAddCommit
    raise Exception("日期不在允许范围内")
Exception: 日期不在允许范围内
2022-05-04 06:24:44|   ERROR|testAction.py[:148]|日期不在允许范围内
Traceback (most recent call last):
  File "/Users/ziqguo/Documents/testdev/testProject/testProject/testAction.py", line 131, in orderAddCommit
    raise Exception("日期不在允许范围内")
Exception: 日期不在允许范围内
2022-05-04 06:24:45|   ERROR|testAction.py[:148]|日期不在允许范围内
Traceback (most recent call last):
  File "/Users/ziqguo/Documents/testdev/testProject/testProject/testAction.py", line 131, in orderAddCommit
    raise Exception("日期不在允许范围内")
Exception: 日期不在允许范围内
2022-05-04 06:24:45|   ERROR|testAction.py[:148]|日期不在允许范围内
Traceback (most recent call last):
  File "/Users/ziqguo/Documents/testdev/testProject/testProject/testAction.py", line 131, in orderAddCommit
    raise Exception("日期不在允许范围内")
Exception: 日期不在允许范围内
2022-05-04 06:24:45|   ERROR|testAction.py[:148]|日期不在允许范围内
Traceback (most recent call last):
  File "/Users/ziqguo/Documents/testdev/testProject/testProject/testAction.py", line 131, in orderAddCommit
    raise Exception("日期不在允许范围内")
Exception: 日期不在允许范围内
2022-05-04 06:31:27|   DEBUG|testAction.py[:57]|admin
2022-05-04 06:31:27|   DEBUG|testAction.py[:58]|123456
2022-05-04 06:31:27|    INFO|testAction.py[:78]|response json: {'code': 0}
2022-05-04 06:31:27|   ERROR|testAction.py[:148]|'order_dep'
Traceback (most recent call last):
  File "/Users/ziqguo/opt/anaconda3/envs/testProject/lib/python3.9/site-packages/django/utils/datastructures.py", line 76, in __getitem__
    list_ = super().__getitem__(key)
KeyError: 'order_dep'

During handling of the above exception, another exception occurred:

Traceback (most recent call last):
  File "/Users/ziqguo/Documents/testdev/testProject/testProject/testAction.py", line 122, in orderAddCommit
    order_dep = request.POST['order_dep']
  File "/Users/ziqguo/opt/anaconda3/envs/testProject/lib/python3.9/site-packages/django/utils/datastructures.py", line 78, in __getitem__
    raise MultiValueDictKeyError(key)
django.utils.datastructures.MultiValueDictKeyError: 'order_dep'
2022-05-04 06:31:27|   ERROR|testAction.py[:148]|日期不在允许范围内
Traceback (most recent call last):
  File "/Users/ziqguo/Documents/testdev/testProject/testProject/testAction.py", line 131, in orderAddCommit
    raise Exception("日期不在允许范围内")
Exception: 日期不在允许范围内
2022-05-04 06:31:27|   ERROR|testAction.py[:148]|日期不在允许范围内
Traceback (most recent call last):
  File "/Users/ziqguo/Documents/testdev/testProject/testProject/testAction.py", line 131, in orderAddCommit
    raise Exception("日期不在允许范围内")
Exception: 日期不在允许范围内
2022-05-04 06:31:27|   ERROR|testAction.py[:148]|'order_date'
Traceback (most recent call last):
  File "/Users/ziqguo/opt/anaconda3/envs/testProject/lib/python3.9/site-packages/django/utils/datastructures.py", line 76, in __getitem__
    list_ = super().__getitem__(key)
KeyError: 'order_date'

During handling of the above exception, another exception occurred:

Traceback (most recent call last):
  File "/Users/ziqguo/Documents/testdev/testProject/testProject/testAction.py", line 124, in orderAddCommit
    order_date = request.POST['order_date']
  File "/Users/ziqguo/opt/anaconda3/envs/testProject/lib/python3.9/site-packages/django/utils/datastructures.py", line 78, in __getitem__
    raise MultiValueDictKeyError(key)
django.utils.datastructures.MultiValueDictKeyError: 'order_date'
2022-05-04 06:31:27|   ERROR|testAction.py[:148]|日期不在允许范围内
Traceback (most recent call last):
  File "/Users/ziqguo/Documents/testdev/testProject/testProject/testAction.py", line 131, in orderAddCommit
    raise Exception("日期不在允许范围内")
Exception: 日期不在允许范围内
2022-05-04 06:31:27|   ERROR|testAction.py[:148]|日期不在允许范围内
Traceback (most recent call last):
  File "/Users/ziqguo/Documents/testdev/testProject/testProject/testAction.py", line 131, in orderAddCommit
    raise Exception("日期不在允许范围内")
Exception: 日期不在允许范围内
2022-05-04 06:31:27|   ERROR|testAction.py[:148]|日期不在允许范围内
Traceback (most recent call last):
  File "/Users/ziqguo/Documents/testdev/testProject/testProject/testAction.py", line 131, in orderAddCommit
    raise Exception("日期不在允许范围内")
Exception: 日期不在允许范围内
2022-05-04 06:31:27|   ERROR|testAction.py[:148]|日期不在允许范围内
Traceback (most recent call last):
  File "/Users/ziqguo/Documents/testdev/testProject/testProject/testAction.py", line 131, in orderAddCommit
    raise Exception("日期不在允许范围内")
Exception: 日期不在允许范围内
2022-05-04 06:31:27|   ERROR|testAction.py[:148]|日期不在允许范围内
Traceback (most recent call last):
  File "/Users/ziqguo/Documents/testdev/testProject/testProject/testAction.py", line 131, in orderAddCommit
    raise Exception("日期不在允许范围内")
Exception: 日期不在允许范围内
2022-05-04 06:31:27|   ERROR|testAction.py[:148]|'order_desc'
Traceback (most recent call last):
  File "/Users/ziqguo/opt/anaconda3/envs/testProject/lib/python3.9/site-packages/django/utils/datastructures.py", line 76, in __getitem__
    list_ = super().__getitem__(key)
KeyError: 'order_desc'

During handling of the above exception, another exception occurred:

Traceback (most recent call last):
  File "/Users/ziqguo/Documents/testdev/testProject/testProject/testAction.py", line 134, in orderAddCommit
    order_desc = request.POST['order_desc']
  File "/Users/ziqguo/opt/anaconda3/envs/testProject/lib/python3.9/site-packages/django/utils/datastructures.py", line 78, in __getitem__
    raise MultiValueDictKeyError(key)
django.utils.datastructures.MultiValueDictKeyError: 'order_desc'
