2022-03-24 02:16:53|   ERROR|log.py[:224]|Internal Server Error: /rand_code/
Traceback (most recent call last):
  File "/Users/ziqguo/opt/anaconda3/envs/testProject/lib/python3.9/site-packages/django/db/backends/utils.py", line 84, in _execute
    return self.cursor.execute(sql, params)
  File "/Users/ziqguo/opt/anaconda3/envs/testProject/lib/python3.9/site-packages/django/db/backends/mysql/base.py", line 73, in execute
    return self.cursor.execute(query, args)
  File "/Users/ziqguo/opt/anaconda3/envs/testProject/lib/python3.9/site-packages/pymysql/cursors.py", line 163, in execute
    result = self._query(query)
  File "/Users/ziqguo/opt/anaconda3/envs/testProject/lib/python3.9/site-packages/pymysql/cursors.py", line 321, in _query
    conn.query(q)
  File "/Users/ziqguo/opt/anaconda3/envs/testProject/lib/python3.9/site-packages/pymysql/connections.py", line 505, in query
    self._affected_rows = self._read_query_result(unbuffered=unbuffered)
  File "/Users/ziqguo/opt/anaconda3/envs/testProject/lib/python3.9/site-packages/pymysql/connections.py", line 724, in _read_query_result
    result.read()
  File "/Users/ziqguo/opt/anaconda3/envs/testProject/lib/python3.9/site-packages/pymysql/connections.py", line 1069, in read
    first_packet = self.connection._read_packet()
  File "/Users/ziqguo/opt/anaconda3/envs/testProject/lib/python3.9/site-packages/pymysql/connections.py", line 676, in _read_packet
    packet.raise_for_error()
  File "/Users/ziqguo/opt/anaconda3/envs/testProject/lib/python3.9/site-packages/pymysql/protocol.py", line 223, in raise_for_error
    err.raise_mysql_exception(self._data)
  File "/Users/ziqguo/opt/anaconda3/envs/testProject/lib/python3.9/site-packages/pymysql/err.py", line 107, in raise_mysql_exception
    raise errorclass(errno, errval)
pymysql.err.ProgrammingError: (1146, "Table 'demodb.django_session' doesn't exist")

The above exception was the direct cause of the following exception:

Traceback (most recent call last):
  File "/Users/ziqguo/opt/anaconda3/envs/testProject/lib/python3.9/site-packages/django/core/handlers/exception.py", line 47, in inner
    response = get_response(request)
  File "/Users/ziqguo/opt/anaconda3/envs/testProject/lib/python3.9/site-packages/django/utils/deprecation.py", line 116, in __call__
    response = self.process_response(request, response)
  File "/Users/ziqguo/opt/anaconda3/envs/testProject/lib/python3.9/site-packages/django/contrib/sessions/middleware.py", line 63, in process_response
    request.session.save()
  File "/Users/ziqguo/opt/anaconda3/envs/testProject/lib/python3.9/site-packages/django/contrib/sessions/backends/db.py", line 81, in save
    return self.create()
  File "/Users/ziqguo/opt/anaconda3/envs/testProject/lib/python3.9/site-packages/django/contrib/sessions/backends/db.py", line 51, in create
    self._session_key = self._get_new_session_key()
  File "/Users/ziqguo/opt/anaconda3/envs/testProject/lib/python3.9/site-packages/django/contrib/sessions/backends/base.py", line 178, in _get_new_session_key
    if not self.exists(session_key):
  File "/Users/ziqguo/opt/anaconda3/envs/testProject/lib/python3.9/site-packages/django/contrib/sessions/backends/db.py", line 47, in exists
    return self.model.objects.filter(session_key=session_key).exists()
  File "/Users/ziqguo/opt/anaconda3/envs/testProject/lib/python3.9/site-packages/django/db/models/query.py", line 809, in exists
    return self.query.has_results(using=self.db)
  File "/Users/ziqguo/opt/anaconda3/envs/testProject/lib/python3.9/site-packages/django/db/models/sql/query.py", line 535, in has_results
    return compiler.has_results()
  File "/Users/ziqguo/opt/anaconda3/envs/testProject/lib/python3.9/site-packages/django/db/models/sql/compiler.py", line 1124, in has_results
    return bool(self.execute_sql(SINGLE))
  File "/Users/ziqguo/opt/anaconda3/envs/testProject/lib/python3.9/site-packages/django/db/models/sql/compiler.py", line 1154, in execute_sql
    cursor.execute(sql, params)
  File "/Users/ziqguo/opt/anaconda3/envs/testProject/lib/python3.9/site-packages/django/db/backends/utils.py", line 98, in execute
    return super().execute(sql, params)
  File "/Users/ziqguo/opt/anaconda3/envs/testProject/lib/python3.9/site-packages/django/db/backends/utils.py", line 66, in execute
    return self._execute_with_wrappers(sql, params, many=False, executor=self._execute)
  File "/Users/ziqguo/opt/anaconda3/envs/testProject/lib/python3.9/site-packages/django/db/backends/utils.py", line 75, in _execute_with_wrappers
    return executor(sql, params, many, context)
  File "/Users/ziqguo/opt/anaconda3/envs/testProject/lib/python3.9/site-packages/django/db/backends/utils.py", line 84, in _execute
    return self.cursor.execute(sql, params)
  File "/Users/ziqguo/opt/anaconda3/envs/testProject/lib/python3.9/site-packages/django/db/utils.py", line 90, in __exit__
    raise dj_exc_value.with_traceback(traceback) from exc_value
  File "/Users/ziqguo/opt/anaconda3/envs/testProject/lib/python3.9/site-packages/django/db/backends/utils.py", line 84, in _execute
    return self.cursor.execute(sql, params)
  File "/Users/ziqguo/opt/anaconda3/envs/testProject/lib/python3.9/site-packages/django/db/backends/mysql/base.py", line 73, in execute
    return self.cursor.execute(query, args)
  File "/Users/ziqguo/opt/anaconda3/envs/testProject/lib/python3.9/site-packages/pymysql/cursors.py", line 163, in execute
    result = self._query(query)
  File "/Users/ziqguo/opt/anaconda3/envs/testProject/lib/python3.9/site-packages/pymysql/cursors.py", line 321, in _query
    conn.query(q)
  File "/Users/ziqguo/opt/anaconda3/envs/testProject/lib/python3.9/site-packages/pymysql/connections.py", line 505, in query
    self._affected_rows = self._read_query_result(unbuffered=unbuffered)
  File "/Users/ziqguo/opt/anaconda3/envs/testProject/lib/python3.9/site-packages/pymysql/connections.py", line 724, in _read_query_result
    result.read()
  File "/Users/ziqguo/opt/anaconda3/envs/testProject/lib/python3.9/site-packages/pymysql/connections.py", line 1069, in read
    first_packet = self.connection._read_packet()
  File "/Users/ziqguo/opt/anaconda3/envs/testProject/lib/python3.9/site-packages/pymysql/connections.py", line 676, in _read_packet
    packet.raise_for_error()
  File "/Users/ziqguo/opt/anaconda3/envs/testProject/lib/python3.9/site-packages/pymysql/protocol.py", line 223, in raise_for_error
    err.raise_mysql_exception(self._data)
  File "/Users/ziqguo/opt/anaconda3/envs/testProject/lib/python3.9/site-packages/pymysql/err.py", line 107, in raise_mysql_exception
    raise errorclass(errno, errval)
django.db.utils.ProgrammingError: (1146, "Table 'demodb.django_session' doesn't exist")
2022-03-24 02:19:06|   DEBUG|selector_events.py[:59]|Using selector: KqueueSelector
2022-03-24 02:22:26|    INFO|testAction.py[:99]|response json: {'code': 0}
2022-03-24 02:23:06|   DEBUG|testAction.py[:57]|admin
2022-03-24 02:23:06|   DEBUG|testAction.py[:58]|123456
2022-03-24 02:23:06|    INFO|testAction.py[:78]|response json: {'code': 0}
2022-03-24 02:23:06|    INFO|testAction.py[:105]|载入主页面...
2022-03-24 02:24:50|   ERROR|testAction.py[:148]|日期不在允许范围内
Traceback (most recent call last):
  File "/Users/ziqguo/Documents/testdev/testProject/testProject/testAction.py", line 131, in orderAddCommit
    raise Exception("日期不在允许范围内")
Exception: 日期不在允许范围内
2022-03-24 02:24:55|   ERROR|testAction.py[:148]|日期不在允许范围内
Traceback (most recent call last):
  File "/Users/ziqguo/Documents/testdev/testProject/testProject/testAction.py", line 131, in orderAddCommit
    raise Exception("日期不在允许范围内")
Exception: 日期不在允许范围内
2022-03-24 02:25:05|   ERROR|testAction.py[:148]|日期不在允许范围内
Traceback (most recent call last):
  File "/Users/ziqguo/Documents/testdev/testProject/testProject/testAction.py", line 131, in orderAddCommit
    raise Exception("日期不在允许范围内")
Exception: 日期不在允许范围内
2022-03-24 02:34:24|   DEBUG|selector_events.py[:59]|Using selector: KqueueSelector
2022-03-24 02:34:36| WARNING|log.py[:224]|Not Found: /
2022-03-24 02:34:40|    INFO|testAction.py[:105]|载入主页面...
